2025-06-23 21:17:01,151 INFO    MainThread:2812876 [wandb_setup.py:_flush():81] Current SDK version is 0.20.1
2025-06-23 21:17:01,151 INFO    MainThread:2812876 [wandb_setup.py:_flush():81] Configure stats pid to 2812876
2025-06-23 21:17:01,151 INFO    MainThread:2812876 [wandb_setup.py:_flush():81] Loading settings from /data/satori_hdd1/mutyuu/.config/wandb/settings
2025-06-23 21:17:01,152 INFO    MainThread:2812876 [wandb_setup.py:_flush():81] Loading settings from /data/satori_hdd1/mutyuu/workspace/LLM_A2Z/examples_trl/wandb/settings
2025-06-23 21:17:01,152 INFO    MainThread:2812876 [wandb_setup.py:_flush():81] Loading settings from environment variables
2025-06-23 21:17:01,152 INFO    MainThread:2812876 [wandb_init.py:setup_run_log_directory():703] Logging user logs to /data/satori_hdd1/mutyuu/workspace/LLM_A2Z/examples_trl/wandb/run-20250623_211701-t03deeao/logs/debug.log
2025-06-23 21:17:01,152 INFO    MainThread:2812876 [wandb_init.py:setup_run_log_directory():704] Logging internal logs to /data/satori_hdd1/mutyuu/workspace/LLM_A2Z/examples_trl/wandb/run-20250623_211701-t03deeao/logs/debug-internal.log
2025-06-23 21:17:01,152 INFO    MainThread:2812876 [wandb_init.py:monkeypatch_ipython():622] configuring jupyter hooks <wandb.sdk.wandb_init._WandbInit object at 0x147dfc1daa10>
2025-06-23 21:17:01,153 INFO    MainThread:2812876 [wandb_init.py:init():831] calling init triggers
2025-06-23 21:17:01,153 INFO    MainThread:2812876 [wandb_init.py:init():836] wandb.init called with sweep_config: {}
config: {'learning_rate': 0.1, 'epochs': 10, 'batch_size': 32, 'optimizer': 'adam', 'dropout_rate': 0.2, '_wandb': {}}
2025-06-23 21:17:01,153 INFO    MainThread:2812876 [wandb_init.py:init():872] starting backend
2025-06-23 21:17:01,385 INFO    MainThread:2812876 [wandb_init.py:init():875] sending inform_init request
2025-06-23 21:17:01,390 INFO    MainThread:2812876 [wandb_init.py:init():883] backend started and connected
2025-06-23 21:17:01,393 INFO    MainThread:2812876 [wandb_run.py:_label_probe_notebook():1299] probe notebook
2025-06-23 21:17:01,394 INFO    MainThread:2812876 [wandb_init.py:init():956] updated telemetry
2025-06-23 21:17:01,409 INFO    MainThread:2812876 [wandb_init.py:init():980] communicating run to backend with 90.0 second timeout
2025-06-23 21:17:44,901 WARNING MainThread:2812876 [wandb_init.py:init():1613] [no run ID] interrupted
Traceback (most recent call last):
  File "/data/satori_hdd1/mutyuu/miniconda3/envs/trl/lib/python3.11/site-packages/wandb/sdk/wandb_init.py", line 1609, in init
    return wi.init(run_settings, run_config, run_printer)
           ^^^^^^^^^^^^^^^^^^^^^^^^^^^^^^^^^^^^^^^^^^^^^^
  File "/data/satori_hdd1/mutyuu/miniconda3/envs/trl/lib/python3.11/site-packages/wandb/sdk/wandb_init.py", line 999, in init
    result = wait_with_progress(
             ^^^^^^^^^^^^^^^^^^^
  File "/data/satori_hdd1/mutyuu/miniconda3/envs/trl/lib/python3.11/site-packages/wandb/sdk/mailbox/wait_with_progress.py", line 24, in wait_with_progress
    return wait_all_with_progress(
           ^^^^^^^^^^^^^^^^^^^^^^^
  File "/data/satori_hdd1/mutyuu/miniconda3/envs/trl/lib/python3.11/site-packages/wandb/sdk/mailbox/wait_with_progress.py", line 87, in wait_all_with_progress
    return asyncio_compat.run(progress_loop_with_timeout)
           ^^^^^^^^^^^^^^^^^^^^^^^^^^^^^^^^^^^^^^^^^^^^^^
  File "/data/satori_hdd1/mutyuu/miniconda3/envs/trl/lib/python3.11/site-packages/wandb/sdk/lib/asyncio_compat.py", line 30, in run
    return future.result()
           ^^^^^^^^^^^^^^^
  File "/data/satori_hdd1/mutyuu/miniconda3/envs/trl/lib/python3.11/concurrent/futures/_base.py", line 451, in result
    self._condition.wait(timeout)
  File "/data/satori_hdd1/mutyuu/miniconda3/envs/trl/lib/python3.11/threading.py", line 327, in wait
    waiter.acquire()
KeyboardInterrupt
2025-06-23 21:17:44,907 WARNING MsgRouterThr:2812876 [router.py:message_loop():63] [no run ID] message_loop has been closed
Traceback (most recent call last):
  File "/data/satori_hdd1/mutyuu/miniconda3/envs/trl/lib/python3.11/site-packages/wandb/sdk/interface/router_sock.py", line 27, in _read_message
    return self._sock_client.read_server_response(timeout=1)
           ^^^^^^^^^^^^^^^^^^^^^^^^^^^^^^^^^^^^^^^^^^^^^^^^^
  File "/data/satori_hdd1/mutyuu/miniconda3/envs/trl/lib/python3.11/site-packages/wandb/sdk/lib/sock_client.py", line 235, in read_server_response
    data = self._read_packet_bytes(timeout=timeout)
           ^^^^^^^^^^^^^^^^^^^^^^^^^^^^^^^^^^^^^^^^
  File "/data/satori_hdd1/mutyuu/miniconda3/envs/trl/lib/python3.11/site-packages/wandb/sdk/lib/sock_client.py", line 220, in _read_packet_bytes
    raise SockClientClosedError
wandb.sdk.lib.sock_client.SockClientClosedError

The above exception was the direct cause of the following exception:

Traceback (most recent call last):
  File "/data/satori_hdd1/mutyuu/miniconda3/envs/trl/lib/python3.11/site-packages/wandb/sdk/interface/router.py", line 56, in message_loop
    msg = self._read_message()
          ^^^^^^^^^^^^^^^^^^^^
  File "/data/satori_hdd1/mutyuu/miniconda3/envs/trl/lib/python3.11/site-packages/wandb/sdk/interface/router_sock.py", line 29, in _read_message
    raise MessageRouterClosedError from e
wandb.sdk.interface.router.MessageRouterClosedError
2025-06-23 21:17:44,921 INFO    MsgRouterThr:2812876 [mailbox.py:close():129] [no run ID] Closing mailbox, abandoning 2 handles.
2025-06-23 21:17:58,366 ERROR   MainThread:2812876 [wandb_init.py:init():1619] [no run ID] error in wandb.init()
Traceback (most recent call last):
  File "/data/satori_hdd1/mutyuu/miniconda3/envs/trl/lib/python3.11/site-packages/wandb/sdk/wandb_init.py", line 1609, in init
    return wi.init(run_settings, run_config, run_printer)
           ^^^^^^^^^^^^^^^^^^^^^^^^^^^^^^^^^^^^^^^^^^^^^^
  File "/data/satori_hdd1/mutyuu/miniconda3/envs/trl/lib/python3.11/site-packages/wandb/sdk/wandb_init.py", line 963, in init
    backend.interface.publish_header()
  File "/data/satori_hdd1/mutyuu/miniconda3/envs/trl/lib/python3.11/site-packages/wandb/sdk/interface/interface.py", line 97, in publish_header
    self._publish_header(header)
  File "/data/satori_hdd1/mutyuu/miniconda3/envs/trl/lib/python3.11/site-packages/wandb/sdk/interface/interface_shared.py", line 275, in _publish_header
    self._publish(rec)
  File "/data/satori_hdd1/mutyuu/miniconda3/envs/trl/lib/python3.11/site-packages/wandb/sdk/interface/interface_sock.py", line 39, in _publish
    self._sock_client.send_record_publish(record)
  File "/data/satori_hdd1/mutyuu/miniconda3/envs/trl/lib/python3.11/site-packages/wandb/sdk/lib/sock_client.py", line 174, in send_record_publish
    self.send_server_request(server_req)
  File "/data/satori_hdd1/mutyuu/miniconda3/envs/trl/lib/python3.11/site-packages/wandb/sdk/lib/sock_client.py", line 154, in send_server_request
    self._send_message(msg)
  File "/data/satori_hdd1/mutyuu/miniconda3/envs/trl/lib/python3.11/site-packages/wandb/sdk/lib/sock_client.py", line 151, in _send_message
    self._sendall_with_error_handle(header + data)
  File "/data/satori_hdd1/mutyuu/miniconda3/envs/trl/lib/python3.11/site-packages/wandb/sdk/lib/sock_client.py", line 130, in _sendall_with_error_handle
    sent = self._sock.send(data)
           ^^^^^^^^^^^^^^^^^^^^^
BrokenPipeError: [Errno 32] Broken pipe
