2025-06-24 19:02:00,133 INFO    MainThread:3378574 [wandb_setup.py:_flush():81] Current SDK version is 0.20.1
2025-06-24 19:02:00,133 INFO    MainThread:3378574 [wandb_setup.py:_flush():81] Configure stats pid to 3378574
2025-06-24 19:02:00,133 INFO    MainThread:3378574 [wandb_setup.py:_flush():81] Loading settings from /data/satori_hdd1/mutyuu/.config/wandb/settings
2025-06-24 19:02:00,133 INFO    MainThread:3378574 [wandb_setup.py:_flush():81] Loading settings from /data/satori_hdd1/mutyuu/workspace/LLM_A2Z/examples_trl/wandb/settings
2025-06-24 19:02:00,133 INFO    MainThread:3378574 [wandb_setup.py:_flush():81] Loading settings from environment variables
2025-06-24 19:02:00,134 INFO    MainThread:3378574 [wandb_init.py:setup_run_log_directory():703] Logging user logs to /data/satori_hdd1/mutyuu/workspace/LLM_A2Z/examples_trl/wandb/run-20250624_190200-9cv1itqd/logs/debug.log
2025-06-24 19:02:00,134 INFO    MainThread:3378574 [wandb_init.py:setup_run_log_directory():704] Logging internal logs to /data/satori_hdd1/mutyuu/workspace/LLM_A2Z/examples_trl/wandb/run-20250624_190200-9cv1itqd/logs/debug-internal.log
2025-06-24 19:02:00,134 INFO    MainThread:3378574 [wandb_init.py:monkeypatch_ipython():622] configuring jupyter hooks <wandb.sdk.wandb_init._WandbInit object at 0x7cbf93948580>
2025-06-24 19:02:00,135 INFO    MainThread:3378574 [wandb_init.py:init():831] calling init triggers
2025-06-24 19:02:00,135 INFO    MainThread:3378574 [wandb_init.py:init():836] wandb.init called with sweep_config: {}
config: {'_wandb': {}}
2025-06-24 19:02:00,135 INFO    MainThread:3378574 [wandb_init.py:init():872] starting backend
2025-06-24 19:02:00,345 INFO    MainThread:3378574 [wandb_init.py:init():875] sending inform_init request
2025-06-24 19:02:00,348 INFO    MainThread:3378574 [wandb_init.py:init():883] backend started and connected
2025-06-24 19:02:00,350 INFO    MainThread:3378574 [wandb_run.py:_label_probe_notebook():1299] probe notebook
2025-06-24 19:02:00,352 INFO    MainThread:3378574 [wandb_init.py:init():956] updated telemetry
2025-06-24 19:02:00,363 INFO    MainThread:3378574 [wandb_init.py:init():980] communicating run to backend with 90.0 second timeout
2025-06-24 19:02:29,639 WARNING MainThread:3378574 [wandb_init.py:init():1613] [no run ID] interrupted
Traceback (most recent call last):
  File "/data/satori_hdd1/mutyuu/.local/lib/python3.10/site-packages/wandb/sdk/wandb_init.py", line 1609, in init
    return wi.init(run_settings, run_config, run_printer)
  File "/data/satori_hdd1/mutyuu/.local/lib/python3.10/site-packages/wandb/sdk/wandb_init.py", line 999, in init
    result = wait_with_progress(
  File "/data/satori_hdd1/mutyuu/.local/lib/python3.10/site-packages/wandb/sdk/mailbox/wait_with_progress.py", line 24, in wait_with_progress
    return wait_all_with_progress(
  File "/data/satori_hdd1/mutyuu/.local/lib/python3.10/site-packages/wandb/sdk/mailbox/wait_with_progress.py", line 87, in wait_all_with_progress
    return asyncio_compat.run(progress_loop_with_timeout)
  File "/data/satori_hdd1/mutyuu/.local/lib/python3.10/site-packages/wandb/sdk/lib/asyncio_compat.py", line 30, in run
    return future.result()
  File "/data/satori_hdd1/mutyuu/miniconda3/envs/simpo/lib/python3.10/concurrent/futures/_base.py", line 453, in result
    self._condition.wait(timeout)
  File "/data/satori_hdd1/mutyuu/miniconda3/envs/simpo/lib/python3.10/threading.py", line 320, in wait
    waiter.acquire()
KeyboardInterrupt
2025-06-24 19:02:29,645 WARNING MsgRouterThr:3378574 [router.py:message_loop():63] [no run ID] message_loop has been closed
Traceback (most recent call last):
  File "/data/satori_hdd1/mutyuu/.local/lib/python3.10/site-packages/wandb/sdk/interface/router_sock.py", line 27, in _read_message
    return self._sock_client.read_server_response(timeout=1)
  File "/data/satori_hdd1/mutyuu/.local/lib/python3.10/site-packages/wandb/sdk/lib/sock_client.py", line 235, in read_server_response
    data = self._read_packet_bytes(timeout=timeout)
  File "/data/satori_hdd1/mutyuu/.local/lib/python3.10/site-packages/wandb/sdk/lib/sock_client.py", line 220, in _read_packet_bytes
    raise SockClientClosedError
wandb.sdk.lib.sock_client.SockClientClosedError

The above exception was the direct cause of the following exception:

Traceback (most recent call last):
  File "/data/satori_hdd1/mutyuu/.local/lib/python3.10/site-packages/wandb/sdk/interface/router.py", line 56, in message_loop
    msg = self._read_message()
  File "/data/satori_hdd1/mutyuu/.local/lib/python3.10/site-packages/wandb/sdk/interface/router_sock.py", line 29, in _read_message
    raise MessageRouterClosedError from e
wandb.sdk.interface.router.MessageRouterClosedError
2025-06-24 19:02:29,651 INFO    MsgRouterThr:3378574 [mailbox.py:close():129] [no run ID] Closing mailbox, abandoning 2 handles.
2025-06-24 19:02:40,218 ERROR   MainThread:3378574 [wandb_init.py:init():1619] [no run ID] error in wandb.init()
Traceback (most recent call last):
  File "/data/satori_hdd1/mutyuu/.local/lib/python3.10/site-packages/wandb/sdk/wandb_init.py", line 1609, in init
    return wi.init(run_settings, run_config, run_printer)
  File "/data/satori_hdd1/mutyuu/.local/lib/python3.10/site-packages/wandb/sdk/wandb_init.py", line 963, in init
    backend.interface.publish_header()
  File "/data/satori_hdd1/mutyuu/.local/lib/python3.10/site-packages/wandb/sdk/interface/interface.py", line 97, in publish_header
    self._publish_header(header)
  File "/data/satori_hdd1/mutyuu/.local/lib/python3.10/site-packages/wandb/sdk/interface/interface_shared.py", line 275, in _publish_header
    self._publish(rec)
  File "/data/satori_hdd1/mutyuu/.local/lib/python3.10/site-packages/wandb/sdk/interface/interface_sock.py", line 39, in _publish
    self._sock_client.send_record_publish(record)
  File "/data/satori_hdd1/mutyuu/.local/lib/python3.10/site-packages/wandb/sdk/lib/sock_client.py", line 174, in send_record_publish
    self.send_server_request(server_req)
  File "/data/satori_hdd1/mutyuu/.local/lib/python3.10/site-packages/wandb/sdk/lib/sock_client.py", line 154, in send_server_request
    self._send_message(msg)
  File "/data/satori_hdd1/mutyuu/.local/lib/python3.10/site-packages/wandb/sdk/lib/sock_client.py", line 151, in _send_message
    self._sendall_with_error_handle(header + data)
  File "/data/satori_hdd1/mutyuu/.local/lib/python3.10/site-packages/wandb/sdk/lib/sock_client.py", line 130, in _sendall_with_error_handle
    sent = self._sock.send(data)
BrokenPipeError: [Errno 32] Broken pipe
2025-06-24 19:02:46,220 ERROR   MainThread:3378574 [wandb_init.py:init():1619] [no run ID] error in wandb.init()
Traceback (most recent call last):
  File "/data/satori_hdd1/mutyuu/.local/lib/python3.10/site-packages/wandb/sdk/wandb_init.py", line 1609, in init
    return wi.init(run_settings, run_config, run_printer)
  File "/data/satori_hdd1/mutyuu/.local/lib/python3.10/site-packages/wandb/sdk/wandb_init.py", line 876, in init
    service.inform_init(
  File "/data/satori_hdd1/mutyuu/.local/lib/python3.10/site-packages/wandb/sdk/lib/service_connection.py", line 147, in inform_init
    self._client.send_server_request(spb.ServerRequest(inform_init=request))
  File "/data/satori_hdd1/mutyuu/.local/lib/python3.10/site-packages/wandb/sdk/lib/sock_client.py", line 154, in send_server_request
    self._send_message(msg)
  File "/data/satori_hdd1/mutyuu/.local/lib/python3.10/site-packages/wandb/sdk/lib/sock_client.py", line 151, in _send_message
    self._sendall_with_error_handle(header + data)
  File "/data/satori_hdd1/mutyuu/.local/lib/python3.10/site-packages/wandb/sdk/lib/sock_client.py", line 130, in _sendall_with_error_handle
    sent = self._sock.send(data)
BrokenPipeError: [Errno 32] Broken pipe
